<?xml version="1.0"?>
<robot xmlns:xacro="http://www.ros.org/wiki/xacro">

  <xacro:macro name="elfin3" params="prefix:='elfin_'">

    <xacro:include filename="$(find elfin_description)/urdf/materials.xacro"/>
    <xacro:include filename="$(find elfin_description)/urdf/elfin_robot.gazebo"/>
    <xacro:include filename="$(find elfin_description)/urdf/elfin_transmission.xacro"/>

    <xacro:property name="density" value="3.09"/>

    <link name="${prefix}base_link"/>

    <joint name="${prefix}base_joint" type="fixed">
      <origin xyz="0 0 0" rpy="0 0 ${pi/2}"/>
      <parent link="${prefix}base_link"/>
      <child link="${prefix}base"/>
    </joint>

    <link name="${prefix}base">
      <visual>
        <origin xyz="0 0 0" rpy="0 0 0"/>
        <geometry>
          <mesh filename="package://elfin_description/meshes/elfin3/elfin_base.STL"/>
        </geometry>
        <material name="metal_white"/>
      </visual>
      <collision>
        <origin xyz="0 0 0" rpy="0 0 0"/>
        <geometry>
          <mesh filename="package://elfin_description/meshes/elfin3/elfin_base.STL"/>
        </geometry>
      </collision>
      <inertial>
        <origin
          xyz="0.000476057496448 -0.00609847721085 0.0271227961552"
          rpy="0 0 0" />
        <mass value="${0.432503561632*density}"/>
        <inertia
          ixx="${0.00107966*density}" ixy="${6.43e-06*density}" ixz="${1.97e-06*density}"
          iyy="${0.00089216*density}" iyz="${-1.269e-05*density}"
          izz="${0.00174712*density}"/>
      </inertial>
    </link>

    <joint name="${prefix}joint1" type="revolute">
      <origin xyz="0 0 0.031" rpy="${pi/2} 0 0"/>
      <parent link="${prefix}base"/>
      <child link="${prefix}link1"/>
      <axis xyz="0 1 0"/>
      <limit lower="-3.14" upper="3.14" effort="104" velocity="1.57"/>
    </joint>

    <link name="${prefix}link1">
      <visual>
        <origin xyz="0 0 0" rpy="0 0 0"/>
        <geometry>
          <mesh filename="package://elfin_description/meshes/elfin3/elfin_link1.STL"/>
        </geometry>
        <material name="metal"/>
      </visual>
      <collision>
        <origin xyz="0 0 0" rpy="0 0 0"/>
        <geometry>
          <mesh filename="package://elfin_description/meshes/elfin3/elfin_link1.STL"/>
        </geometry>
      </collision>
      <inertial>
        <origin
          xyz="-0.0192425632808 0.120157543892 -2.05350524914e-05"
          rpy="0 0 0" />
        <mass value="${1.52001312557*density}"/>
        <inertia
          ixx="${0.00523815*density}" ixy="${0.00122593*density}" ixz="${-1.6e-07*density}"
          iyy="${0.00315471*density}" iyz="${-6.4e-07*density}"
          izz="${0.00646649*density}" />
      </inertial>
    </link>

    <joint name="${prefix}joint2" type="revolute">
      <origin xyz="-0.068808 0.1615 0" rpy="0 0 0"/>
      <parent link="${prefix}link1"/>
      <child link="${prefix}link2"/>
      <axis xyz="-1 0 0"/>
      <limit lower="-2.35" upper="2.35" effort="104" velocity="1.57"/>
    </joint>

    <link name="${prefix}link2">
      <visual>
        <origin xyz="0 0 0" rpy="0 0 0"/>
        <geometry>
          <mesh filename="package://elfin_description/meshes/elfin3/elfin_link2.STL"/>
        </geometry>
        <material name="metal_grey"/>
      </visual>
      <collision>
        <origin xyz="0 0 0" rpy="0 0 0"/>
        <geometry>
          <mesh filename="package://elfin_description/meshes/elfin3/elfin_link2.STL"/>
        </geometry>
      </collision>
      <inertial>
        <origin
          xyz="-0.0363359816546 0.121774838175 -3.84046105722e-05"
          rpy="0 0 0" />
        <mass value="${0.519672255247*density}"/>
        <inertia
          ixx="${0.00564813*density}" ixy="${-0.00026473*density}" ixz="${0.0*density}"
          iyy="${0.00053594*density}" iyz="${1.29e-06*density}"
          izz="${0.00545618*density}"/>
      </inertial>
    </link>

    <joint name="${prefix}joint3" type="revolute">
      <origin xyz="0 0.266 0" rpy="${-pi} 0 0"/>
      <parent link="${prefix}link2"/>
      <child link="${prefix}link3"/>
      <axis xyz="1 0 0" />
      <limit lower="-2.61" upper="2.61" effort="69" velocity="1.57" />
    </joint>

    <link name="${prefix}link3">
      <visual>
        <origin xyz="0 0 0" rpy="0 0 0" />
        <geometry>
          <mesh filename="package://elfin_description/meshes/elfin3/elfin_link3.STL" />
        </geometry>
        <material name="metal"/>
      </visual>
      <collision>
        <origin xyz="0 0 0" rpy="0 0 0"/>
        <geometry>
          <mesh filename="package://elfin_description/meshes/elfin3/elfin_link3.STL" />
        </geometry>
      </collision>
      <inertial>
        <origin
          xyz="0.0513625008301 -0.0377418700977 -1.41484011876e-05"
          rpy="0 0 0" />
        <mass value="${1.07514585114*density}"/>
        <inertia
          ixx="${0.00296619*density}" ixy="${0.00072021*density}" ixz="${7.3e-07*density}"
          iyy="${0.00182263*density}" iyz="${-3.7e-07*density}"
          izz="${0.00372855*density}" />
        </inertial>
    </link>

    <joint name="${prefix}joint4" type="revolute">
      <origin xyz="0.068808 -0.10523 0" rpy="${pi} 0 0"/>
      <parent link="${prefix}link3"/>
      <child link="${prefix}link4"/>
      <axis xyz="0 1 0"/>
      <limit lower="-3.14" upper="3.14" effort="69" velocity="1.57"/>
    </joint>

    <link name="${prefix}link4">
      <visual>
        <origin xyz="0 0 0" rpy="0 0 0" />
        <geometry>
          <mesh filename="package://elfin_description/meshes/elfin3/elfin_link4.STL" />
        </geometry>
        <material name="metal_grey"/>
      </visual>
      <collision>
        <origin xyz="0 0 0" rpy="0 0 0" />
        <geometry>
          <mesh filename="package://elfin_description/meshes/elfin3/elfin_link4.STL" />
        </geometry>
      </collision>
      <inertial>
        <origin
          xyz="-0.0580853772834 0.10002233137 -3.45203877103e-06"
          rpy="0 0 0" />
        <mass value="${0.37026646381*density}"/>
        <inertia
          ixx="${0.00238279*density}" ixy="${0.00082955*density}" ixz="${1.1e-07*density}"
          iyy="${0.00095758*density}" iyz="${-3.2e-07*density}"
          izz="${0.00285161*density}"/>
        </inertial>
    </link>

    <joint name="${prefix}joint5" type="revolute">
      <origin xyz="0 0.21877 0" rpy="${-pi} 0 0"/>
      <parent link="elfin_link4"/>
      <child link="elfin_link5"/>
      <axis xyz="1 0 0"/>
      <limit lower="-2.56" upper="2.56" effort="34" velocity="1.57" />
    </joint>

    <link name="${prefix}link5">
      <visual>
        <origin xyz="0 0 0" rpy="0 0 0" />
        <geometry>
          <mesh filename="package://elfin_description/meshes/elfin3/elfin_link5.STL" />
        </geometry>
        <material name="metal"/>
      </visual>
      <collision>
        <origin xyz="0 0 0" rpy="0 0 0" />
        <geometry>
          <mesh filename="package://elfin_description/meshes/elfin3/elfin_link5.STL" />
        </geometry>
      </collision>
      <inertial>
        <origin
          xyz="-0.0158710385319 -0.0365214098995 4.94388107361e-07"
          rpy="0 0 0" />
        <mass value="${0.807027243448*density}"/>
        <inertia
          ixx="${0.00193719*density}" ixy="${0.00047145*density}" ixz="${2e-08*density}"
          iyy="${0.00112857*density}" iyz="${-1.1e-07*density}"
          izz="${0.00245655*density}" />
        </inertial>
    </link>

    <joint name="${prefix}joint6" type="revolute">
      <origin xyz="0 -0.1065 0" rpy="${-pi} 0 ${-pi}"/>
      <parent link="${prefix}link5"/>
      <child link="${prefix}link6"/>
      <axis xyz="0 -1 0"/>
      <limit lower="-3.14" upper="3.14" effort="34" velocity="1.57"/>
    </joint>

    <link name="${prefix}link6">
      <visual>
        <origin xyz="0 0 0" rpy="0 0 0"/>
        <geometry>
          <mesh filename="package://elfin_description/meshes/elfin3/elfin_link6.STL"/>
        </geometry>
        <material name="metal_white"/>
      </visual>
      <collision>
        <origin xyz="0 0 0" rpy="0 0 0"/>
        <geometry>
          <mesh filename="package://elfin_description/meshes/elfin3/elfin_link6.STL"/>
        </geometry>
      </collision>
      <inertial>
        <origin
          xyz="-0.0009237 -0.042691 -0.0003367"
          rpy="0 0 0" />
        <mass value="${0.147312*density}"/>
        <inertia
          ixx="${0.00019407*density}" ixy="${1.4e-06*density}" ixz="${-2.89e-06*density}"
          iyy="${0.00019592*density}" iyz="${5e-08*density}"
          izz="${0.00019496*density}"/>
        </inertial>
    </link>

    <joint name="${prefix}end_joint" type="fixed">
      <origin xyz="0 -0.091 0" rpy="${pi/2} ${-pi/2} 0"/>
      <parent link="${prefix}link6"/>
      <child link="${prefix}end_link"/>
    </joint>

    <link name="${prefix}end_link"/>

  </xacro:macro>

</robot>
