<?xml version="1.0"?>
<robot xmlns:xacro="http://www.ros.org/wiki/xacro">

  <xacro:macro name="elfin5" params="prefix:='elfin_'">

    <xacro:include filename="$(find elfin_description)/urdf/materials.xacro" />
    <xacro:include filename="$(find elfin_description)/urdf/elfin_robot.gazebo" />
    <xacro:include filename="$(find elfin_description)/urdf/elfin_transmission.xacro" />

    <xacro:property name="density" value="3.09"/>

    <link name="${prefix}base_link"/>

    <joint name="${prefix}base_joint" type="fixed">
      <origin xyz="0 0 0" rpy="0 0 ${pi/2}"/>
      <parent link="${prefix}base_link"/>
      <child link="${prefix}base"/>
    </joint>

    <link name="${prefix}base">
      <visual>
        <origin xyz="0 0 0" rpy="0 0 0"/>
        <geometry>
          <mesh filename="package://elfin_description/meshes/elfin5/elfin_base.STL"/>
        </geometry>
        <material name="metal_white"/>
      </visual>
      <collision>
        <origin xyz="0 0 0" rpy="0 0 0"/>
        <geometry>
          <mesh filename="package://elfin_description/meshes/elfin5/elfin_base.STL"/>
        </geometry>
      </collision>
      <inertial>
        <origin
          xyz="0.000209 0.001319 0.025619"
          rpy="0 0 0" />
        <mass value="${0.690521*density}"/>
        <inertia
          ixx="${0.00130611*density}" ixy="${0.0000568*density}" ixz="${0.00000189*density}"
          iyy="${0.00134467*density}" iyz="${0.00001095*density}"
          izz="${0.00229139*density}" />
      </inertial>
    </link>

    <joint name="${prefix}joint1" type="revolute">
      <origin xyz="0 0 0.03" rpy="${pi/2} 0 0"/>
      <parent link="${prefix}base"/>
      <child link="${prefix}link1"/>
      <axis xyz="0 1 0"/>
      <limit lower="-3.14" upper="3.14" effort="200" velocity="1.57"/>
    </joint>

    <link name="${prefix}link1">
      <visual>
        <origin xyz="0 0 0" rpy="0 0 0"/>
        <geometry>
          <mesh filename="package://elfin_description/meshes/elfin5/elfin_link1.STL"/>
        </geometry>
        <material name="metal"/>
      </visual>
      <collision>
        <origin xyz="0 0 0" rpy="0 0 0"/>
        <geometry>
          <mesh filename="package://elfin_description/meshes/elfin5/elfin_link1.STL"/>
        </geometry>
      </collision>
      <inertial>
        <origin
          xyz="-0.0217491 0.1389011 0.0000125"
          rpy="0 0 0" />
        <mass value="${2.576772*density}"/>
        <inertia
          ixx="${0.01298966*density}" ixy="${0.00287966*density}" ixz="${-0.000001*density}"
          iyy="${0.00721115*density}" iyz="${-0.00000052*density}"
          izz="${0.01532713*density}" />
      </inertial>
    </link>

    <joint name="${prefix}joint2" type="revolute">
      <origin xyz="-0.078069 0.19 0" rpy="0 0 0"/>
      <parent link="${prefix}link1"/>
      <child link="${prefix}link2"/>
      <axis xyz="-1 0 0"/>
      <limit lower="-2.35" upper="2.35" effort="200" velocity="1.57"/>
    </joint>

    <link name="${prefix}link2">
      <visual>
        <origin xyz="0 0 0" rpy="0 0 0"/>
        <geometry>
          <mesh filename="package://elfin_description/meshes/elfin5/elfin_link2.STL"/>
        </geometry>
        <material name="metal_grey"/>
      </visual>
      <collision>
        <origin xyz="0 0 0" rpy="0 0 0"/>
        <geometry>
          <mesh filename="package://elfin_description/meshes/elfin5/elfin_link2.STL"/>
        </geometry>
      </collision>
      <inertial>
        <origin xyz="-0.0522485 0.1580101 -0.0000003" rpy="0 0 0" />
        <mass value="${1.208607*density}"/>
        <inertia
          ixx="${0.02975970*density}" ixy="${-0.00126441*density}" ixz="${-0.00000024*density}"
          iyy="${0.00168156*density}" iyz="${-0.0000021*density}"
          izz="${0.02944694*density}"/>
      </inertial>
    </link>

    <joint name="${prefix}joint3" type="revolute">
      <origin xyz="0 0.38 0" rpy="${pi} 0 0"/>
      <parent link="${prefix}link2"/>
      <child link="${prefix}link3"/>
      <axis xyz="1 0 0"/>
      <limit lower="-2.61" upper="2.61" effort="104" velocity="1.57"/>
    </joint>

    <link name="${prefix}link3">
      <visual>
        <origin xyz="0 0 0" rpy="0 0 0"/>
        <geometry>
          <mesh filename="package://elfin_description/meshes/elfin5/elfin_link3.STL"/>
        </geometry>
        <material name="metal"/>
      </visual>
      <collision>
        <origin xyz="0 0 0" rpy="0 0 0"/>
        <geometry>
          <mesh filename="package://elfin_description/meshes/elfin5/elfin_link3.STL"/>
        </geometry>
      </collision>
      <inertial>
        <origin
          xyz="0.0587091 -0.0414608 -0.0000210"
          rpy="0 0 0" />
        <mass value="${1.525883*density}"/>
        <inertia
          ixx="${0.00527835*density}" ixy="${0.00124150*density}" ixz="${-0.00000018*density}"
          iyy="${0.00317861*density}" iyz="${-0.00000067*density}"
          izz="${0.00652527*density}"/>
      </inertial>
    </link>

    <joint name="e${prefix}joint4" type="revolute">
      <origin xyz="0.078069 -0.11342 0" rpy="${-pi} 0 0"/>
      <parent link="${prefix}link3"/>
      <child link="${prefix}link4"/>
      <axis xyz="0 1 0"/>
      <limit lower="-3.14" upper="3.14" effort="104" velocity="1.57"/>
    </joint>

    <link name="${prefix}link4">
      <visual>
        <origin xyz="0 0 0" rpy="0 0 0"/>
        <geometry>
          <mesh filename="package://elfin_description/meshes/elfin5/elfin_link4.STL"/>
        </geometry>
        <material name="metal_grey"/>
      </visual>
      <collision>
        <origin xyz="0 0 0" rpy="0 0 0"/>
        <geometry>
          <mesh filename="package://elfin_description/meshes/elfin5/elfin_link4.STL"/>
        </geometry>
      </collision>
      <inertial>
        <origin
          xyz="-0.0587964 0.1436154 -0.0000478"
          rpy="0 0 0" />
        <mass value="${0.475026*density}"/>
        <inertia
          ixx="${0.00542441*density}" ixy="${0.00155092*density}" ixz="${-0.00000053*density}"
          iyy="${0.00131780*density}" iyz="${0.00000195*density}"
          izz="${0.00607489*density}" />
      </inertial>
    </link>

    <joint name="${prefix}joint5" type="revolute">
      <origin xyz="0 0.30658 0" rpy="${-pi} 0 0"/>
      <parent link="${prefix}link4"/>
      <child link="${prefix}link5"/>
      <axis xyz="1 0 0"/>
      <limit lower="-2.56" upper="2.56" effort="34" velocity="1.57"/>
    </joint>

    <link name="${prefix}link5">
      <visual>
        <origin xyz="0 0 0" rpy="0 0 0"/>
        <geometry>
          <mesh filename="package://elfin_description/meshes/elfin5/elfin_link5.STL"/>
        </geometry>
        <material name="metal"/>
      </visual>
      <collision>
        <origin xyz="0 0 0" rpy="0 0 0"/>
        <geometry>
          <mesh filename="package://elfin_description/meshes/elfin5/elfin_link5.STL"/>
        </geometry>
      </collision>
      <inertial>
        <origin
          xyz="-0.0159154 -0.0365660 0.0000004"
          rpy="0 0 0" />
        <mass value="${0.808399*density}"/>
        <inertia
          ixx="${0.00194399*density}" ixy="${0.00047414*density}" ixz="${0.00000001*density}"
          iyy="${0.00113245*density}" iyz="${-0.00000012*density}"
          izz="${0.00246661*density}" />
      </inertial>
    </link>

    <joint name="e${prefix}joint6" type="revolute">
      <origin xyz="0 -0.1065 0" rpy="0 0 0"/>
      <parent link="${prefix}link5"/>
      <child link="${prefix}link6"/>
      <axis xyz="0 -1 0"/>
      <limit lower="-3.14" upper="3.14" effort="34" velocity="1.57"/>
    </joint>

    <link name="${prefix}link6">
      <visual>
        <origin xyz="0 0 0" rpy="0 0 0"/>
        <geometry>
          <mesh filename="package://elfin_description/meshes/elfin5/elfin_link6.STL"/>
        </geometry>
        <material name="metal_white"/>
      </visual>
      <collision>
        <origin xyz="0 0 0" rpy="0 0 0"/>
        <geometry>
          <mesh filename="package://elfin_description/meshes/elfin5/elfin_link6.STL"/>
        </geometry>
      </collision>
      <inertial>
        <origin
          xyz="-0.0009237 -0.042691 -0.0003367" 
          rpy="0 0 0"/>
        <mass value="${0.147312*density}"/>
        <inertia
          ixx="${0.00019407*density}" ixy="${1.4e-06*density}" ixz="${-2.89e-06*density}"
          iyy="${0.00019592*density}" iyz="${5e-08*density}"
          izz="${0.00019496*density}" />
      </inertial>
    </link>

    <joint name="${prefix}end_joint" type="fixed">
      <origin xyz="0 -0.0735 0" rpy="${pi/2} ${pi/2} 0"/>
      <parent link="${prefix}link6"/>
      <child link="${prefix}end_link"/>
    </joint>

    <link name="${prefix}end_link"/>

  </xacro:macro>

</robot>
